Workbook

Sheet Титульник
A1: Коллективный МАИ
A2: Принятое правило | B2: Описание
A3: Метод | B3: Чёткий коллективный МАИ (обычные числовые матрицы Саати).
A4: Шкала | B4: Основные вербальные градации: 9, 7, 5, 3, 1 и обратные 1/3, 1/5, 1/7, 1/9.
A5: Агрегирование экспертов | B5: Геометрическое среднее одинаковых парных суждений трёх экспертов.
A6: Веса | B6: Нормированное геометрическое среднее строк матрицы.

Sheet Шкала_Саати
A1: Шкала Саати и случайный индекс RI
A3: Ответ формы | B3: Число Саати | D3: n | E3: RI
A4: Первый вариант — крайне предпочтительнее | B4: 9 | D4: 1 | E4: 0
A5: Первый вариант — очень сильно предпочтительнее | B5: 7 | D5: 2 | E5: 0
A6: Первый вариант — сильно предпочтительнее | B6: 5 | D6: 3 | E6: 0.58
A7: Первый вариант — умеренно предпочтительнее | B7: 3 | D7: 4 | E7: 0.9
A8: Равнозначны | B8: 1 | D8: 5 | E8: 1.12
A9: Второй вариант — умеренно предпочтительнее | B9: 0.33333333 | D9: 6 | E9: 1.24
A10: Второй вариант — сильно предпочтительнее | B10: 0.2 | D10: 7 | E10: 1.32
A11: Второй вариант — очень сильно предпочтительнее | B11: 0.14285714 | D11: 8 | E11: 1.41
A12: Второй вариант — крайне предпочтительнее | B12: 0.11111111 | D12: 9 | E12: 1.45
D13: 10 | E13: 1.49

Sheet Ответы_Forms
A1: Отметка времени | B1: ВАШЕ ИМЯ | C1: C1 Актуальность и острота проблемы ↔ C2 Влияние на продуктивность труда | D1: C1 Актуальность и острота проблемы ↔ C3 Влияние на качество условий труда | E1: C1 Актуальность и острота проблемы ↔ C4 Экономическая выгода для предприятия | F1: C1 Актуальность и острота проблемы ↔ C5 Техническая сложность реализации | G1: C1 Актуальность и острота проблемы ↔ C6 Ресурсоёмкость разработки (стоимость и сроки) | H1: C2 Влияние на продуктивность труда ↔ C3 Влияние на качество условий труда | I1: C2 Влияние на продуктивность труда ↔ C4 Экономическая выгода для предприятия | J1: C2 Влияние на продуктивность труда ↔ C5 Техническая сложность реализации | K1: C2 Влияние на продуктивность труда ↔ C6 Ресурсоёмкость разработки (стоимость и сроки) | L1: C3 Влияние на качество условий труда ↔ C4 Экономическая выгода для предприятия | M1: C3 Влияние на качество условий труда ↔ C5 Техническая сложность реализации | N1: C3 Влияние на качество условий труда ↔ C6 Ресурсоёмкость разработки (стоимость и сроки) | O1: C4 Экономическая выгода для предприятия ↔ C5 Техническая сложность реализации | P1: C4 Экономическая выгода для предприятия ↔ C6 Ресурсоёмкость разработки (стоимость и сроки) | Q1: C5 Техническая сложность реализации ↔ C6 Ресурсоёмкость разработки (стоимость и сроки) | R1: A1 Ассистент продуктивности ↔ A2 Внутренние заявки | S1: A1 Ассистент продуктивности ↔ A3 Обучение и адаптация | T1: A1 Ассистент продуктивности ↔ A4 Графики смен | U1: A2 Внутренние заявки ↔ A3 Обучение и адаптация | V1: A2 Внутренние заявки ↔ A4 Графики смен | W1: A3 Обучение и адаптация ↔ A4 Графики смен | X1: A1 Ассистент продуктивности ↔ A2 Внутренние заявки | Y1: A1 Ассистент продуктивности ↔ A3 Обучение и адаптация | Z1: A1 Ассистент продуктивности ↔ A4 Графики смен | AA1: A2 Внутренние заявки ↔ A3 Обучение и адаптация | AB1: A2 Внутренние заявки ↔ A4 Графики смен | AC1: A3 Обучение и адаптация ↔ A4 Графики смен | AD1: A1 Ассистент продуктивности ↔ A2 Внутренние заявки | AE1: A1 Ассистент продуктивности ↔ A3 Обучение и адаптация | AF1: A1 Ассистент продуктивности ↔ A4 Графики смен | AG1: A2 Внутренние заявки ↔ A3 Обучение и адаптация | AH1: A2 Внутренние заявки ↔ A4 Графики смен | AI1: A3 Обучение и адаптация ↔ A4 Графики смен | AJ1: A1 Ассистент продуктивности ↔ A2 Внутренние заявки | AK1: A1 Ассистент продуктивности ↔ A3 Обучение и адаптация | AL1: A1 Ассистент продуктивности ↔ A4 Графики смен | AM1: A2 Внутренние заявки ↔ A3 Обучение и адаптация | AN1: A2 Внутренние заявки ↔ A4 Графики смен | AO1: A3 Обучение и адаптация ↔ A4 Графики смен | AP1: A1 Ассистент продуктивности ↔ A2 Внутренние заявки | AQ1: A1 Ассистент продуктивности ↔ A3 Обучение и адаптация | AR1: A1 Ассистент продуктивности ↔ A4 Графики смен | AS1: A2 Внутренние заявки ↔ A3 Обучение и адаптация | AT1: A2 Внутренние заявки ↔ A4 Графики смен | AU1: A3 Обучение и адаптация ↔ A4 Графики смен | AV1: A1 Ассистент продуктивности ↔ A2 Внутренние заявки | AW1: A1 Ассистент продуктивности ↔ A3 Обучение и адаптация | AX1: A1 Ассистент продуктивности ↔ A4 Графики смен | AY1: A2 Внутренние заявки ↔ A3 Обучение и адаптация | AZ1: A2 Внутренние заявки ↔ A4 Графики смен | BA1: A3 Обучение и адаптация ↔ A4 Графики смен
A2: 46305.451 | B2: Бредихин | C2: Первый вариант — очень сильно предпочтительнее | D2: Первый вариант — сильно предпочтительнее | E2: Равнозначны | F2: Первый вариант — очень сильно предпочтительнее | G2: Первый вариант — очень сильно предпочтительнее | H2: Первый вариант — умеренно предпочтительнее | I2: Второй вариант — очень сильно предпочтительнее | J2: Первый вариант — очень сильно предпочтительнее | K2: Первый вариант — сильно предпочтительнее | L2: Второй вариант — очень сильно предпочтительнее | M2: Равнозначны | N2: Второй вариант — умеренно предпочтительнее | O2: Первый вариант — очень сильно предпочтительнее | P2: Первый вариант — очень сильно предпочтительнее | Q2: Равнозначны | R2: Второй вариант — сильно предпочтительнее | S2: Второй вариант — умеренно предпочтительнее | T2: Первый вариант — умеренно предпочтительнее | U2: Первый вариант — умеренно предпочтительнее | V2: Первый вариант — умеренно предпочтительнее | W2: Первый вариант — очень сильно предпочтительнее | X2: Равнозначны | Y2: Первый вариант — сильно предпочтительнее | Z2: Первый вариант — умеренно предпочтительнее | AA2: Первый вариант — сильно предпочтительнее | AB2: Первый вариант — умеренно предпочтительнее | AC2: Первый вариант — умеренно предпочтительнее | AD2: Первый вариант — сильно предпочтительнее | AE2: Второй вариант — крайне предпочтительнее | AF2: Первый вариант — сильно предпочтительнее | AG2: Второй вариант — очень сильно предпочтительнее | AH2: Второй вариант — сильно предпочтительнее | AI2: Первый вариант — умеренно предпочтительнее | AJ2: Первый вариант — сильно предпочтительнее | AK2: Первый вариант — крайне предпочтительнее | AL2: Первый вариант — сильно предпочтительнее | AM2: Первый вариант — умеренно предпочтительнее | AN2: Второй вариант — умеренно предпочтительнее | AO2: Второй вариант — очень сильно предпочтительнее | AP2: Второй вариант — сильно предпочтительнее | AQ2: Второй вариант — сильно предпочтительнее | AR2: Равнозначны | AS2: Первый вариант — умеренно предпочтительнее | AT2: Первый вариант — очень сильно предпочтительнее | AU2: Первый вариант — очень сильно предпочтительнее | AV2: Второй вариант — очень сильно предпочтительнее | AW2: Первый вариант — умеренно предпочтительнее | AX2: Первый вариант — очень сильно предпочтительнее | AY2: Первый вариант — крайне предпочтительнее | AZ2: Первый вариант — крайне предпочтительнее | BA2: Равнозначны
A3: 46305.862 | B3: Символокова | C3: Равнозначны | D3: Первый вариант — сильно предпочтительнее | E3: Равнозначны | F3: Равнозначны | G3: Равнозначны | H3: Первый вариант — сильно предпочтительнее | I3: Равнозначны | J3: Равнозначны | K3: Равнозначны | L3: Второй вариант — сильно предпочтительнее | M3: Второй вариант — умеренно предпочтительнее | N3: Второй вариант — умеренно предпочтительнее | O3: Равнозначны | P3: Равнозначны | Q3: Равнозначны | R3: Второй вариант — сильно предпочтительнее | S3: Второй вариант — сильно предпочтительнее | T3: Равнозначны | U3: Равнозначны | V3: Первый вариант — сильно предпочтительнее | W3: Первый вариант — сильно предпочтительнее | X3: Второй вариант — очень сильно предпочтительнее | Y3: Второй вариант — сильно предпочтительнее | Z3: Второй вариант — умеренно предпочтительнее | AA3: Первый вариант — умеренно предпочтительнее | AB3: Первый вариант — умеренно предпочтительнее | AC3: Равнозначны | AD3: Первый вариант — умеренно предпочтительнее | AE3: Равнозначны | AF3: Равнозначны | AG3: Второй вариант — умеренно предпочтительнее | AH3: Второй вариант — умеренно предпочтительнее | AI3: Равнозначны | AJ3: Второй вариант — очень сильно предпочтительнее | AK3: Второй вариант — сильно предпочтительнее | AL3: Второй вариант — сильно предпочтительнее | AM3: Первый вариант — сильно предпочтительнее | AN3: Первый вариант — сильно предпочтительнее | AO3: Равнозначны | AP3: Второй вариант — умеренно предпочтительнее | AQ3: Второй вариант — умеренно предпочтительнее | AR3: Первый вариант — умеренно предпочтительнее | AS3: Равнозначны | AT3: Первый вариант — сильно предпочтительнее | AU3: Первый вариант — сильно предпочтительнее | AV3: Второй вариант — умеренно предпочтительнее | AW3: Второй вариант — умеренно предпочтительнее | AX3: Первый вариант — умеренно предпочтительнее | AY3: Равнозначны | AZ3: Первый вариант — сильно предпочтительнее | BA3: Первый вариант — сильно предпочтительнее
A4: 46305.926 | B4: Недикова | C4: Первый вариант — умеренно предпочтительнее | D4: Первый вариант — крайне предпочтительнее | E4: Второй вариант — умеренно предпочтительнее | F4: Первый вариант — умеренно предпочтительнее | G4: Первый вариант — сильно предпочтительнее | H4: Первый вариант — сильно предпочтительнее | I4: Второй вариант — сильно предпочтительнее | J4: Первый вариант — умеренно предпочтительнее | K4: Равнозначны | L4: Второй вариант — сильно предпочтительнее | M4: Второй вариант — умеренно предпочтительнее | N4: Второй вариант — умеренно предпочтительнее | O4: Первый вариант — сильно предпочтительнее | P4: Первый вариант — умеренно предпочтительнее | Q4: Равнозначны | R4: Второй вариант — сильно предпочтительнее | S4: Второй вариант — умеренно предпочтительнее | T4: Равнозначны | U4: Первый вариант — умеренно предпочтительнее | V4: Первый вариант — сильно предпочтительнее | W4: Первый вариант — сильно предпочтительнее | X4: Второй вариант — умеренно предпочтительнее | Y4: Равнозначны | Z4: Первый вариант — умеренно предпочтительнее | AA4: Первый вариант — умеренно предпочтительнее | AB4: Первый вариант — умеренно предпочтительнее | AC4: Равнозначны | AD4: Первый вариант — умеренно предпочтительнее | AE4: Равнозначны | AF4: Первый вариант — умеренно предпочтительнее | AG4: Второй вариант — сильно предпочтительнее | AH4: Второй вариант — умеренно предпочтительнее | AI4: Первый вариант — умеренно предпочтительнее | AJ4: Второй вариант — умеренно предпочтительнее | AK4: Первый вариант — умеренно предпочтительнее | AL4: Равнозначны | AM4: Первый вариант — умеренно предпочтительнее | AN4: Равнозначны | AO4: Второй вариант — умеренно предпочтительнее | AP4: Второй вариант — сильно предпочтительнее | AQ4: Второй вариант — умеренно предпочтительнее | AR4: Равнозначны | AS4: Равнозначны | AT4: Первый вариант — очень сильно предпочтительнее | AU4: Первый вариант — сильно предпочтительнее | AV4: Второй вариант — сильно предпочтительнее | AW4: Первый вариант — умеренно предпочтительнее | AX4: Первый вариант — умеренно предпочтительнее | AY4: Первый вариант — умеренно предпочтительнее | AZ4: Первый вариант — очень сильно предпочтительнее | BA4: Первый вариант — сильно предпочтительнее

Sheet Числовые_ответы
A1: Эксперт | B1: Отметка времени | C1: K_C1_C2 | D1: K_C1_C3 | E1: K_C1_C4 | F1: K_C1_C5 | G1: K_C1_C6 | H1: K_C2_C3 | I1: K_C2_C4 | J1: K_C2_C5 | K1: K_C2_C6 | L1: K_C3_C4 | M1: K_C3_C5 | N1: K_C3_C6 | O1: K_C4_C5 | P1: K_C4_C6 | Q1: K_C5_C6 | R1: C1_A1_A2 | S1: C1_A1_A3 | T1: C1_A1_A4 | U1: C1_A2_A3 | V1: C1_A2_A4 | W1: C1_A3_A4 | X1: C2_A1_A2 | Y1: C2_A1_A3 | Z1: C2_A1_A4 | AA1: C2_A2_A3 | AB1: C2_A2_A4 | AC1: C2_A3_A4 | AD1: C3_A1_A2 | AE1: C3_A1_A3 | AF1: C3_A1_A4 | AG1: C3_A2_A3 | AH1: C3_A2_A4 | AI1: C3_A3_A4 | AJ1: C4_A1_A2 | AK1: C4_A1_A3 | AL1: C4_A1_A4 | AM1: C4_A2_A3 | AN1: C4_A2_A4 | AO1: C4_A3_A4 | AP1: C5_A1_A2 | AQ1: C5_A1_A3 | AR1: C5_A1_A4 | AS1: C5_A2_A3 | AT1: C5_A2_A4 | AU1: C5_A3_A4 | AV1: C6_A1_A2 | AW1: C6_A1_A3 | AX1: C6_A1_A4 | AY1: C6_A2_A3 | AZ1: C6_A2_A4 | BA1: C6_A3_A4
A2: Недикова | B2: =IFERROR(INDEX(Ответы_Forms!$A$2:$A$10,MATCH($A2,Ответы_Forms!$B$2:$B$10,0)),"") -> 46305.926 | C2: =IFERROR(VLOOKUP(INDEX(Ответы_Forms!C$2:C$10,MATCH($A2,Ответы_Forms!$B$2:$B$10,0)),Шкала_Саати!$A$4:$B$12,2,FALSE),"") -> 3 | D2: =IFERROR(VLOOKUP(INDEX(Ответы_Forms!D$2:D$10,MATCH($A2,Ответы_Forms!$B$2:$B$10,0)),Шкала_Саати!$A$4:$B$12,2,FALSE),"") -> 9 | E2: =IFERROR(VLOOKUP(INDEX(Ответы_Forms!E$2:E$10,MATCH($A2,Ответы_Forms!$B$2:$B$10,0)),Шкала_Саати!$A$4:$B$12,2,FALSE),"") -> 0.33333333 | F2: =IFERROR(VLOOKUP(INDEX(Ответы_Forms!F$2:F$10,MATCH($A2,Ответы_Forms!$B$2:$B$10,0)),Шкала_Саати!$A$4:$B$12,2,FALSE),"") -> 3 | G2: =IFERROR(VLOOKUP(INDEX(Ответы_Forms!G$2:G$10,MATCH($A2,Ответы_Forms!$B$2:$B$10,0)),Шкала_Саати!$A$4:$B$12,2,FALSE),"") -> 5 | H2: =IFERROR(VLOOKUP(INDEX(Ответы_Forms!H$2:H$10,MATCH($A2,Ответы_Forms!$B$2:$B$10,0)),Шкала_Саати!$A$4:$B$12,2,FALSE),"") -> 5 | I2: =IFERROR(VLOOKUP(INDEX(Ответы_Forms!I$2:I$10,MATCH($A2,Ответы_Forms!$B$2:$B$10,0)),Шкала_Саати!$A$4:$B$12,2,FALSE),"") -> 0.2 | J2: =IFERROR(VLOOKUP(INDEX(Ответы_Forms!J$2:J$10,MATCH($A2,Ответы_Forms!$B$2:$B$10,0)),Шкала_Саати!$A$4:$B$12,2,FALSE),"") -> 3 | ... BA2: =IFERROR(VLOOKUP(INDEX(Ответы_Forms!BA$2:BA$10,MATCH($A2,Ответы_Forms!$B$2:$B$10,0)),Шкала_Саати!$A$4:$B$12,2,FALSE),"") -> 5
A3: Символокова | B3: =IFERROR(INDEX(Ответы_Forms!$A$2:$A$10,MATCH($A3,Ответы_Forms!$B$2:$B$10,0)),"") -> 46305.862 | C3: =IFERROR(VLOOKUP(INDEX(Ответы_Forms!C$2:C$10,MATCH($A3,Ответы_Forms!$B$2:$B$10,0)),Шкала_Саати!$A$4:$B$12,2,FALSE),"") -> 1 | D3: =IFERROR(VLOOKUP(INDEX(Ответы_Forms!D$2:D$10,MATCH($A3,Ответы_Forms!$B$2:$B$10,0)),Шкала_Саати!$A$4:$B$12,2,FALSE),"") -> 5 | E3: =IFERROR(VLOOKUP(INDEX(Ответы_Forms!E$2:E$10,MATCH($A3,Ответы_Forms!$B$2:$B$10,0)),Шкала_Саати!$A$4:$B$12,2,FALSE),"") -> 1 | F3: =IFERROR(VLOOKUP(INDEX(Ответы_Forms!F$2:F$10,MATCH($A3,Ответы_Forms!$B$2:$B$10,0)),Шкала_Саати!$A$4:$B$12,2,FALSE),"") -> 1 | G3: =IFERROR(VLOOKUP(INDEX(Ответы_Forms!G$2:G$10,MATCH($A3,Ответы_Forms!$B$2:$B$10,0)),Шкала_Саати!$A$4:$B$12,2,FALSE),"") -> 1 | H3: =IFERROR(VLOOKUP(INDEX(Ответы_Forms!H$2:H$10,MATCH($A3,Ответы_Forms!$B$2:$B$10,0)),Шкала_Саати!$A$4:$B$12,2,FALSE),"") -> 5 | I3: =IFERROR(VLOOKUP(INDEX(Ответы_Forms!I$2:I$10,MATCH($A3,Ответы_Forms!$B$2:$B$10,0)),Шкала_Саати!$A$4:$B$12,2,FALSE),"") -> 1 | J3: =IFERROR(VLOOKUP(INDEX(Ответы_Forms!J$2:J$10,MATCH($A3,Ответы_Forms!$B$2:$B$10,0)),Шкала_Саати!$A$4:$B$12,2,FALSE),"") -> 1 | ... BA3: =IFERROR(VLOOKUP(INDEX(Ответы_Forms!BA$2:BA$10,MATCH($A3,Ответы_Forms!$B$2:$B$10,0)),Шкала_Саати!$A$4:$B$12,2,FALSE),"") -> 5
A4: Бредихин | B4: =IFERROR(INDEX(Ответы_Forms!$A$2:$A$10,MATCH($A4,Ответы_Forms!$B$2:$B$10,0)),"") -> 46305.451 | C4: =IFERROR(VLOOKUP(INDEX(Ответы_Forms!C$2:C$10,MATCH($A4,Ответы_Forms!$B$2:$B$10,0)),Шкала_Саати!$A$4:$B$12,2,FALSE),"") -> 7 | D4: =IFERROR(VLOOKUP(INDEX(Ответы_Forms!D$2:D$10,MATCH($A4,Ответы_Forms!$B$2:$B$10,0)),Шкала_Саати!$A$4:$B$12,2,FALSE),"") -> 5 | E4: =IFERROR(VLOOKUP(INDEX(Ответы_Forms!E$2:E$10,MATCH($A4,Ответы_Forms!$B$2:$B$10,0)),Шкала_Саати!$A$4:$B$12,2,FALSE),"") -> 1 | F4: =IFERROR(VLOOKUP(INDEX(Ответы_Forms!F$2:F$10,MATCH($A4,Ответы_Forms!$B$2:$B$10,0)),Шкала_Саати!$A$4:$B$12,2,FALSE),"") -> 7 | G4: =IFERROR(VLOOKUP(INDEX(Ответы_Forms!G$2:G$10,MATCH($A4,Ответы_Forms!$B$2:$B$10,0)),Шкала_Саати!$A$4:$B$12,2,FALSE),"") -> 7 | H4: =IFERROR(VLOOKUP(INDEX(Ответы_Forms!H$2:H$10,MATCH($A4,Ответы_Forms!$B$2:$B$10,0)),Шкала_Саати!$A$4:$B$12,2,FALSE),"") -> 3 | I4: =IFERROR(VLOOKUP(INDEX(Ответы_Forms!I$2:I$10,MATCH($A4,Ответы_Forms!$B$2:$B$10,0)),Шкала_Саати!$A$4:$B$12,2,FALSE),"") -> 0.14285714 | J4: =IFERROR(VLOOKUP(INDEX(Ответы_Forms!J$2:J$10,MATCH($A4,Ответы_Forms!$B$2:$B$10,0)),Шкала_Саати!$A$4:$B$12,2,FALSE),"") -> 7 | ... BA4: =IFERROR(VLOOKUP(INDEX(Ответы_Forms!BA$2:BA$10,MATCH($A4,Ответы_Forms!$B$2:$B$10,0)),Шкала_Саати!$A$4:$B$12,2,FALSE),"") -> 1

Sheet Недикова
A1: Индивидуальный МАИ — Недикова
A2: Все матрицы строятся из ответов формы. Нижний треугольник рассчитывается как обратные значения; веса — нормированное геометрическое среднее строк.
A4: Матрица важности критериев
B5: C1 | C5: C2 | D5: C3 | E5: C4 | F5: C5 | G5: C6 | H5: Геом. ср. | I5: Вес | J5: A·w | K5: λ_i
A6: C1 | B6: 1 | C6: =Числовые_ответы!C2 -> 3 | D6: =Числовые_ответы!D2 -> 9 | E6: =Числовые_ответы!E2 -> 0.33333333 | F6: =Числовые_ответы!F2 -> 3 | G6: =Числовые_ответы!G2 -> 5 | H6: =IF(COUNT(B6:G6)<6,"",PRODUCT(B6:G6)^(1/6)) -> 2.2649344 | I6: =IF(H12="","",H6/H12) -> 0.27713944 | J6: =IF(I6="","",B6*$I$6 + C6*$I$7 + D6*$I$8 + E6*$I$9 + F6*$I$10 + G6*$I$11) -> 1.7869788 | K6: =IFERROR(J6/I6,"") -> 6.4479412
A7: C2 | B7: =IF(C6="","",1/C6) -> 0.33333333 | C7: 1 | D7: =Числовые_ответы!H2 -> 5 | E7: =Числовые_ответы!I2 -> 0.2 | F7: =Числовые_ответы!J2 -> 3 | G7: =Числовые_ответы!K2 -> 1 | H7: =IF(COUNT(B7:G7)<6,"",PRODUCT(B7:G7)^(1/6)) -> 1 | I7: =IF(H12="","",H7/H12) -> 0.12236091 | J7: =IF(I7="","",B7*$I$6 + C7*$I$7 + D7*$I$8 + E7*$I$9 + F7*$I$10 + G7*$I$11) -> 0.7929889 | K7: =IFERROR(J7/I7,"") -> 6.480737
A8: C3 | B8: =IF(D6="","",1/D6) -> 0.11111111 | C8: =IF(D7="","",1/D7) -> 0.2 | D8: 1 | E8: =Числовые_ответы!L2 -> 0.2 | F8: =Числовые_ответы!M2 -> 0.33333333 | G8: =Числовые_ответы!N2 -> 0.33333333 | H8: =IF(COUNT(B8:G8)<6,"",PRODUCT(B8:G8)^(1/6)) -> 0.28114422 | I8: =IF(H12="","",H8/H12) -> 0.034401064 | J8: =IF(I8="","",B8*$I$6 + C8*$I$7 + D8*$I$8 + E8*$I$9 + F8*$I$10 + G8*$I$11) -> 0.22575137 | K8: =IFERROR(J8/I8,"") -> 6.562337
A9: C4 | B9: =IF(E6="","",1/E6) -> 3 | C9: =IF(E7="","",1/E7) -> 5 | D9: =IF(E8="","",1/E8) -> 5 | E9: 1 | F9: =Числовые_ответы!O2 -> 5 | G9: =Числовые_ответы!P2 -> 3 | H9: =IF(COUNT(B9:G9)<6,"",PRODUCT(B9:G9)^(1/6)) -> 3.2249681 | I9: =IF(H12="","",H9/H12) -> 0.39461004 | J9: =IF(I9="","",B9*$I$6 + C9*$I$7 + D9*$I$8 + E9*$I$9 + F9*$I$10 + G9*$I$11) -> 2.6801362 | K9: =IFERROR(J9/I9,"") -> 6.7918601
A10: C5 | B10: =IF(F6="","",1/F6) -> 0.33333333 | C10: =IF(F7="","",1/F7) -> 0.33333333 | D10: =IF(F8="","",1/F8) -> 3 | E10: =IF(F9="","",1/F9) -> 0.2 | F10: 1 | G10: =Числовые_ответы!Q2 -> 1 | H10: =IF(COUNT(B10:G10)<6,"",PRODUCT(B10:G10)^(1/6)) -> 0.63677322 | I10: =IF(H12="","",H10/H12) -> 0.077916153 | J10: =IF(I10="","",B10*$I$6 + C10*$I$7 + D10*$I$8 + E10*$I$9 + F10*$I$10 + G10*$I$11) -> 0.48678052 | K10: =IFERROR(J10/I10,"") -> 6.2474918
A11: C6 | B11: =IF(G6="","",1/G6) -> 0.2 | C11: =IF(G7="","",1/G7) -> 1 | D11: =IF(G8="","",1/G8) -> 3 | E11: =IF(G9="","",1/G9) -> 0.33333333 | F11: =IF(G10="","",1/G10) -> 1 | G11: 1 | H11: =IF(COUNT(B11:G11)<6,"",PRODUCT(B11:G11)^(1/6)) -> 0.76472449 | I11: =IF(H12="","",H11/H12) -> 0.093572387 | J11: =IF(I11="","",B11*$I$6 + C11*$I$7 + D11*$I$8 + E11*$I$9 + F11*$I$10 + G11*$I$11) -> 0.58401721 | K11: =IFERROR(J11/I11,"") -> 6.2413414
H12: =IF(COUNT(H6:H11)<6,"",SUM(H6:H11)) -> 8.1725444 | I12: =IF(COUNT(I6:I11)<6,"",SUM(I6:I11)) -> 1 | J12: λmax | K12: =IF(COUNT(K6:K11)<6,"",AVERAGE(K6:K11)) -> 6.4619514
J13: CI | K13: =IF(K12="","",(K12-6)/(6-1)) -> 0.092390281
J14: RI | K14: =VLOOKUP(6,Шкала_Саати!$D$4:$E$13,2,FALSE) -> 1.24
J15: CR | K15: =IF(COUNT(K13:K14)<2,"",K13/K14) -> 0.074508291
A18: C1: Актуальность и острота проблемы
B19: A1 | C19: A2 | D19: A3 | E19: A4 | F19: Геом. ср. | G19: Вес | H19: A·w | I19: λ_i
A20: A1 | B20: 1 | C20: =Числовые_ответы!R2 -> 0.2 | D20: =Числовые_ответы!S2 -> 0.33333333 | E20: =Числовые_ответы!T2 -> 1 | F20: =IF(COUNT(B20:E20)<4,"",PRODUCT(B20:E20)^(1/4)) -> 0.50813275 | G20: =IF(F24="","",F20/F24) -> 0.094211605 | H20: =IF(G20="","",B20*$G$20 + C20*$G$21 + D20*$G$22 + E20*$G$23) -> 0.37866919 | I20: =IFERROR(H20/G20,"") -> 4.0193476
A21: A2 | B21: =IF(C20="","",1/C20) -> 5 | C21: 1 | D21: =Числовые_ответы!U2 -> 3 | E21: =Числовые_ответы!V2 -> 5 | F21: =IF(COUNT(B21:E21)<4,"",PRODUCT(B21:E21)^(1/4)) -> 2.942831 | G21: =IF(F24="","",F21/F24) -> 0.54562283 | H21: =IF(G21="","",B21*$G$20 + C21*$G$21 + D21*$G$22 + E21*$G$23) -> 2.263011 | I21: =IFERROR(H21/G21,"") -> 4.147574
A22: A3 | B22: =IF(D20="","",1/D20) -> 3 | C22: =IF(D21="","",1/D21) -> 0.33333333 | D22: 1 | E22: =Числовые_ответы!W2 -> 5 | F22: =IF(COUNT(B22:E22)<4,"",PRODUCT(B22:E22)^(1/4)) -> 1.4953488 | G22: =IF(F24="","",F22/F24) -> 0.27724883 | H22: =IF(G22="","",B22*$G$20 + C22*$G$21 + D22*$G$22 + E22*$G$23) -> 1.1563416 | I22: =IFERROR(H22/G22,"") -> 4.1707719
A23: A4 | B23: =IF(E20="","",1/E20) -> 1 | C23: =IF(E21="","",1/E21) -> 0.2 | D23: =IF(E22="","",1/E22) -> 0.2 | E23: 1 | F23: =IF(COUNT(B23:E23)<4,"",PRODUCT(B23:E23)^(1/4)) -> 0.4472136 | G23: =IF(F24="","",F23/F24) -> 0.082916739 | H23: =IF(G23="","",B23*$G$20 + C23*$G$21 + D23*$G$22 + E23*$G$23) -> 0.34170268 | I23: =IFERROR(H23/G23,"") -> 4.1210337
F24: =IF(COUNT(F20:F23)<4,"",SUM(F20:F23)) -> 5.3935261 | G24: =IF(COUNT(G20:G23)<4,"",SUM(G20:G23)) -> 1 | H24: λmax | I24: =IF(COUNT(I20:I23)<4,"",AVERAGE(I20:I23)) -> 4.1146818
H25: CI | I25: =IF(I24="","",(I24-4)/(4-1)) -> 0.038227258
H26: RI | I26: =VLOOKUP(4,Шкала_Саати!$D$4:$E$13,2,FALSE) -> 0.9
H27: CR | I27: =IF(COUNT(I25:I26)<2,"",I25/I26) -> 0.042474731
A30: C2: Влияние на продуктивность труда
B31: A1 | C31: A2 | D31: A3 | E31: A4 | F31: Геом. ср. | G31: Вес | H31: A·w | I31: λ_i
A32: A1 | B32: 1 | C32: =Числовые_ответы!X2 -> 0.33333333 | D32: =Числовые_ответы!Y2 -> 1 | E32: =Числовые_ответы!Z2 -> 3 | F32: =IF(COUNT(B32:E32)<4,"",PRODUCT(B32:E32)^(1/4)) -> 1 | G32: =IF(F36="","",F32/F36) -> 0.21660526 | H32: =IF(G32="","",B32*$G$32 + C32*$G$33 + D32*$G$34 + E32*$G$35) -> 0.9209454 | I32: =IFERROR(H32/G32,"") -> 4.2517222
A33: A2 | B33: =IF(C32="","",1/C32) -> 3 | C33: 1 | D33: =Числовые_ответы!AA2 -> 3 | E33: =Числовые_ответы!AB2 -> 3 | F33: =IF(COUNT(B33:E33)<4,"",PRODUCT(B33:E33)^(1/4)) -> 2.2795071 | G33: =IF(F36="","",F33/F36) -> 0.49375322 | H33: =IF(G33="","",B33*$G$32 + C33*$G$33 + D33*$G$34 + E33*$G$35) -> 2.0124936 | I33: =IFERROR(H33/G33,"") -> 4.0759097
A34: A3 | B34: =IF(D32="","",1/D32) -> 1 | C34: =IF(D33="","",1/D33) -> 0.33333333 | D34: 1 | E34: =Числовые_ответы!AC2 -> 1 | F34: =IF(COUNT(B34:E34)<4,"",PRODUCT(B34:E34)^(1/4)) -> 0.75983569 | G34: =IF(F36="","",F34/F36) -> 0.16458441 | H34: =IF(G34="","",B34*$G$32 + C34*$G$33 + D34*$G$34 + E34*$G$35) -> 0.67083118 | I34: =IFERROR(H34/G34,"") -> 4.0759097
A35: A4 | B35: =IF(E32="","",1/E32) -> 0.33333333 | C35: =IF(E33="","",1/E33) -> 0.33333333 | D35: =IF(E34="","",1/E34) -> 1 | E35: 1 | F35: =IF(COUNT(B35:E35)<4,"",PRODUCT(B35:E35)^(1/4)) -> 0.57735027 | G35: =IF(F36="","",F35/F36) -> 0.12505711 | H35: =IF(G35="","",B35*$G$32 + C35*$G$33 + D35*$G$34 + E35*$G$35) -> 0.52642768 | I35: =IFERROR(H35/G35,"") -> 4.2094983
F36: =IF(COUNT(F32:F35)<4,"",SUM(F32:F35)) -> 4.616693 | G36: =IF(COUNT(G32:G35)<4,"",SUM(G32:G35)) -> 1 | H36: λmax | I36: =IF(COUNT(I32:I35)<4,"",AVERAGE(I32:I35)) -> 4.15326
H37: CI | I37: =IF(I36="","",(I36-4)/(4-1)) -> 0.051086656
H38: RI | I38: =VLOOKUP(4,Шкала_Саати!$D$4:$E$13,2,FALSE) -> 0.9
H39: CR | I39: =IF(COUNT(I37:I38)<2,"",I37/I38) -> 0.056762951
A42: C3: Влияние на качество условий труда
B43: A1 | C43: A2 | D43: A3 | E43: A4 | F43: Геом. ср. | G43: Вес | H43: A·w | I43: λ_i
A44: A1 | B44: 1 | C44: =Числовые_ответы!AD2 -> 3 | D44: =Числовые_ответы!AE2 -> 1 | E44: =Числовые_ответы!AF2 -> 3 | F44: =IF(COUNT(B44:E44)<4,"",PRODUCT(B44:E44)^(1/4)) -> 1.7320508 | G44: =IF(F48="","",F44/F48) -> 0.35742061 | H44: =IF(G44="","",B44*$G$44 + C44*$G$45 + D44*$G$46 + E44*$G$47) -> 1.4729424 | I44: =IFERROR(H44/G44,"") -> 4.1210337
A45: A2 | B45: =IF(C44="","",1/C44) -> 0.33333333 | C45: 1 | D45: =Числовые_ответы!AG2 -> 0.2 | E45: =Числовые_ответы!AH2 -> 0.33333333 | F45: =IF(COUNT(B45:E45)<4,"",PRODUCT(B45:E45)^(1/4)) -> 0.3860974 | G45: =IF(F48="","",F45/F48) -> 0.079673855 | H45: =IF(G45="","",B45*$G$44 + C45*$G$45 + D45*$G$46 + E45*$G$47) -> 0.33230147 | I45: =IFERROR(H45/G45,"") -> 4.1707719
A46: A3 | B46: =IF(D44="","",1/D44) -> 1 | C46: =IF(D45="","",1/D45) -> 5 | D46: 1 | E46: =Числовые_ответы!AI2 -> 3 | F46: =IF(COUNT(B46:E46)<4,"",PRODUCT(B46:E46)^(1/4)) -> 1.9679897 | G46: =IF(F48="","",F46/F48) -> 0.40610821 | H46: =IF(G46="","",B46*$G$44 + C46*$G$45 + D46*$G$46 + E46*$G$47) -> 1.6322901 | I46: =IFERROR(H46/G46,"") -> 4.0193476
A47: A4 | B47: =IF(E44="","",1/E44) -> 0.33333333 | C47: =IF(E45="","",1/E45) -> 3 | D47: =IF(E46="","",1/E46) -> 0.33333333 | E47: 1 | F47: =IF(COUNT(B47:E47)<4,"",PRODUCT(B47:E47)^(1/4)) -> 0.75983569 | G47: =IF(F48="","",F47/F48) -> 0.15679732 | H47: =IF(G47="","",B47*$G$44 + C47*$G$45 + D47*$G$46 + E47*$G$47) -> 0.6503285 | I47: =IFERROR(H47/G47,"") -> 4.147574
...

Sheet Символокова
A1: Индивидуальный МАИ — Символокова
A2: Все матрицы строятся из ответов формы. Нижний треугольник рассчитывается как обратные значения; веса — нормированное геометрическое среднее строк.
A4: Матрица важности критериев
B5: C1 | C5: C2 | D5: C3 | E5: C4 | F5: C5 | G5: C6 | H5: Геом. ср. | I5: Вес | J5: A·w | K5: λ_i
A6: C1 | B6: 1 | C6: =Числовые_ответы!C3 -> 1 | D6: =Числовые_ответы!D3 -> 5 | E6: =Числовые_ответы!E3 -> 1 | F6: =Числовые_ответы!F3 -> 1 | G6: =Числовые_ответы!G3 -> 1 | H6: =IF(COUNT(B6:G6)<6,"",PRODUCT(B6:G6)^(1/6)) -> 1.3076605 | I6: =IF(H12="","",H6/H12) -> 0.19708713 | J6: =IF(I6="","",B6*$I$6 + C6*$I$7 + D6*$I$8 + E6*$I$9 + F6*$I$10 + G6*$I$11) -> 1.1869381 | K6: =IFERROR(J6/I6,"") -> 6.0224029
A7: C2 | B7: =IF(C6="","",1/C6) -> 1 | C7: 1 | D7: =Числовые_ответы!H3 -> 5 | E7: =Числовые_ответы!I3 -> 1 | F7: =Числовые_ответы!J3 -> 1 | G7: =Числовые_ответы!K3 -> 1 | H7: =IF(COUNT(B7:G7)<6,"",PRODUCT(B7:G7)^(1/6)) -> 1.3076605 | I7: =IF(H12="","",H7/H12) -> 0.19708713 | J7: =IF(I7="","",B7*$I$6 + C7*$I$7 + D7*$I$8 + E7*$I$9 + F7*$I$10 + G7*$I$11) -> 1.1869381 | K7: =IFERROR(J7/I7,"") -> 6.0224029
A8: C3 | B8: =IF(D6="","",1/D6) -> 0.2 | C8: =IF(D7="","",1/D7) -> 0.2 | D8: 1 | E8: =Числовые_ответы!L3 -> 0.2 | F8: =Числовые_ответы!M3 -> 0.33333333 | G8: =Числовые_ответы!N3 -> 0.33333333 | H8: =IF(COUNT(B8:G8)<6,"",PRODUCT(B8:G8)^(1/6)) -> 0.31008059 | I8: =IF(H12="","",H8/H12) -> 0.046734526 | J8: =IF(I8="","",B8*$I$6 + C8*$I$7 + D8*$I$8 + E8*$I$9 + F8*$I$10 + G8*$I$11) -> 0.28565483 | K8: =IFERROR(J8/I8,"") -> 6.1122869
A9: C4 | B9: =IF(E6="","",1/E6) -> 1 | C9: =IF(E7="","",1/E7) -> 1 | D9: =IF(E8="","",1/E8) -> 5 | E9: 1 | F9: =Числовые_ответы!O3 -> 1 | G9: =Числовые_ответы!P3 -> 1 | H9: =IF(COUNT(B9:G9)<6,"",PRODUCT(B9:G9)^(1/6)) -> 1.3076605 | I9: =IF(H12="","",H9/H12) -> 0.19708713 | J9: =IF(I9="","",B9*$I$6 + C9*$I$7 + D9*$I$8 + E9*$I$9 + F9*$I$10 + G9*$I$11) -> 1.1869381 | K9: =IFERROR(J9/I9,"") -> 6.0224029
A10: C5 | B10: =IF(F6="","",1/F6) -> 1 | C10: =IF(F7="","",1/F7) -> 1 | D10: =IF(F8="","",1/F8) -> 3 | E10: =IF(F9="","",1/F9) -> 1 | F10: 1 | G10: =Числовые_ответы!Q3 -> 1 | H10: =IF(COUNT(B10:G10)<6,"",PRODUCT(B10:G10)^(1/6)) -> 1.200937 | I10: =IF(H12="","",H10/H12) -> 0.18100204 | J10: =IF(I10="","",B10*$I$6 + C10*$I$7 + D10*$I$8 + E10*$I$9 + F10*$I$10 + G10*$I$11) -> 1.0934691 | K10: =IFERROR(J10/I10,"") -> 6.0411973
A11: C6 | B11: =IF(G6="","",1/G6) -> 1 | C11: =IF(G7="","",1/G7) -> 1 | D11: =IF(G8="","",1/G8) -> 3 | E11: =IF(G9="","",1/G9) -> 1 | F11: =IF(G10="","",1/G10) -> 1 | G11: 1 | H11: =IF(COUNT(B11:G11)<6,"",PRODUCT(B11:G11)^(1/6)) -> 1.200937 | I11: =IF(H12="","",H11/H12) -> 0.18100204 | J11: =IF(I11="","",B11*$I$6 + C11*$I$7 + D11*$I$8 + E11*$I$9 + F11*$I$10 + G11*$I$11) -> 1.0934691 | K11: =IFERROR(J11/I11,"") -> 6.0411973
H12: =IF(COUNT(H6:H11)<6,"",SUM(H6:H11)) -> 6.634936 | I12: =IF(COUNT(I6:I11)<6,"",SUM(I6:I11)) -> 1 | J12: λmax | K12: =IF(COUNT(K6:K11)<6,"",AVERAGE(K6:K11)) -> 6.0436484
J13: CI | K13: =IF(K12="","",(K12-6)/(6-1)) -> 0.0087296761
J14: RI | K14: =VLOOKUP(6,Шкала_Саати!$D$4:$E$13,2,FALSE) -> 1.24
J15: CR | K15: =IF(COUNT(K13:K14)<2,"",K13/K14) -> 0.0070400613
A18: C1: Актуальность и острота проблемы
B19: A1 | C19: A2 | D19: A3 | E19: A4 | F19: Геом. ср. | G19: Вес | H19: A·w | I19: λ_i
A20: A1 | B20: 1 | C20: =Числовые_ответы!R3 -> 0.2 | D20: =Числовые_ответы!S3 -> 0.2 | E20: =Числовые_ответы!T3 -> 1 | F20: =IF(COUNT(B20:E20)<4,"",PRODUCT(B20:E20)^(1/4)) -> 0.4472136 | G20: =IF(F24="","",F20/F24) -> 0.083333333 | H20: =IF(G20="","",B20*$G$20 + C20*$G$21 + D20*$G$22 + E20*$G$23) -> 0.33333333 | I20: =IFERROR(H20/G20,"") -> 4
A21: A2 | B21: =IF(C20="","",1/C20) -> 5 | C21: 1 | D21: =Числовые_ответы!U3 -> 1 | E21: =Числовые_ответы!V3 -> 5 | F21: =IF(COUNT(B21:E21)<4,"",PRODUCT(B21:E21)^(1/4)) -> 2.236068 | G21: =IF(F24="","",F21/F24) -> 0.41666667 | H21: =IF(G21="","",B21*$G$20 + C21*$G$21 + D21*$G$22 + E21*$G$23) -> 1.6666667 | I21: =IFERROR(H21/G21,"") -> 4
A22: A3 | B22: =IF(D20="","",1/D20) -> 5 | C22: =IF(D21="","",1/D21) -> 1 | D22: 1 | E22: =Числовые_ответы!W3 -> 5 | F22: =IF(COUNT(B22:E22)<4,"",PRODUCT(B22:E22)^(1/4)) -> 2.236068 | G22: =IF(F24="","",F22/F24) -> 0.41666667 | H22: =IF(G22="","",B22*$G$20 + C22*$G$21 + D22*$G$22 + E22*$G$23) -> 1.6666667 | I22: =IFERROR(H22/G22,"") -> 4
A23: A4 | B23: =IF(E20="","",1/E20) -> 1 | C23: =IF(E21="","",1/E21) -> 0.2 | D23: =IF(E22="","",1/E22) -> 0.2 | E23: 1 | F23: =IF(COUNT(B23:E23)<4,"",PRODUCT(B23:E23)^(1/4)) -> 0.4472136 | G23: =IF(F24="","",F23/F24) -> 0.083333333 | H23: =IF(G23="","",B23*$G$20 + C23*$G$21 + D23*$G$22 + E23*$G$23) -> 0.33333333 | I23: =IFERROR(H23/G23,"") -> 4
F24: =IF(COUNT(F20:F23)<4,"",SUM(F20:F23)) -> 5.3665631 | G24: =IF(COUNT(G20:G23)<4,"",SUM(G20:G23)) -> 1 | H24: λmax | I24: =IF(COUNT(I20:I23)<4,"",AVERAGE(I20:I23)) -> 4
H25: CI | I25: =IF(I24="","",(I24-4)/(4-1)) -> 0
H26: RI | I26: =VLOOKUP(4,Шкала_Саати!$D$4:$E$13,2,FALSE) -> 0.9
H27: CR | I27: =IF(COUNT(I25:I26)<2,"",I25/I26) -> 0
A30: C2: Влияние на продуктивность труда
B31: A1 | C31: A2 | D31: A3 | E31: A4 | F31: Геом. ср. | G31: Вес | H31: A·w | I31: λ_i
A32: A1 | B32: 1 | C32: =Числовые_ответы!X3 -> 0.14285714 | D32: =Числовые_ответы!Y3 -> 0.2 | E32: =Числовые_ответы!Z3 -> 0.33333333 | F32: =IF(COUNT(B32:E32)<4,"",PRODUCT(B32:E32)^(1/4)) -> 0.31239399 | G32: =IF(F36="","",F32/F36) -> 0.059323651 | H32: =IF(G32="","",B32*$G$32 + C32*$G$33 + D32*$G$34 + E32*$G$35) -> 0.24220704 | I32: =IFERROR(H32/G32,"") -> 4.0828074
A33: A2 | B33: =IF(C32="","",1/C32) -> 7 | C33: 1 | D33: =Числовые_ответы!AA3 -> 3 | E33: =Числовые_ответы!AB3 -> 3 | F33: =IF(COUNT(B33:E33)<4,"",PRODUCT(B33:E33)^(1/4)) -> 2.8173132 | G33: =IF(F36="","",F33/F36) -> 0.53500807 | H33: =IF(G33="","",B33*$G$32 + C33*$G$33 + D33*$G$34 + E33*$G$35) -> 2.1672785 | I33: =IFERROR(H33/G33,"") -> 4.0509266
A34: A3 | B34: =IF(D32="","",1/D32) -> 5 | C34: =IF(D33="","",1/D33) -> 0.33333333 | D34: 1 | E34: =Числовые_ответы!AC3 -> 1 | F34: =IF(COUNT(B34:E34)<4,"",PRODUCT(B34:E34)^(1/4)) -> 1.1362194 | G34: =IF(F36="","",F34/F36) -> 0.21576817 | H34: =IF(G34="","",B34*$G$32 + C34*$G$33 + D34*$G$34 + E34*$G$35) -> 0.88062256 | I34: =IFERROR(H34/G34,"") -> 4.0813367
A35: A4 | B35: =IF(E32="","",1/E32) -> 3 | C35: =IF(E33="","",1/E33) -> 0.33333333 | D35: =IF(E34="","",1/E34) -> 1 | E35: 1 | F35: =IF(COUNT(B35:E35)<4,"",PRODUCT(B35:E35)^(1/4)) -> 1 | G35: =IF(F36="","",F35/F36) -> 0.1899001 | H35: =IF(G35="","",B35*$G$32 + C35*$G$33 + D35*$G$34 + E35*$G$35) -> 0.76197525 | I35: =IFERROR(H35/G35,"") -> 4.0125058
F36: =IF(COUNT(F32:F35)<4,"",SUM(F32:F35)) -> 5.2659266 | G36: =IF(COUNT(G32:G35)<4,"",SUM(G32:G35)) -> 1 | H36: λmax | I36: =IF(COUNT(I32:I35)<4,"",AVERAGE(I32:I35)) -> 4.0568941
H37: CI | I37: =IF(I36="","",(I36-4)/(4-1)) -> 0.018964709
H38: RI | I38: =VLOOKUP(4,Шкала_Саати!$D$4:$E$13,2,FALSE) -> 0.9
H39: CR | I39: =IF(COUNT(I37:I38)<2,"",I37/I38) -> 0.021071899
A42: C3: Влияние на качество условий труда
B43: A1 | C43: A2 | D43: A3 | E43: A4 | F43: Геом. ср. | G43: Вес | H43: A·w | I43: λ_i
A44: A1 | B44: 1 | C44: =Числовые_ответы!AD3 -> 3 | D44: =Числовые_ответы!AE3 -> 1 | E44: =Числовые_ответы!AF3 -> 1 | F44: =IF(COUNT(B44:E44)<4,"",PRODUCT(B44:E44)^(1/4)) -> 1.316074 | G44: =IF(F48="","",F44/F48) -> 0.3 | H44: =IF(G44="","",B44*$G$44 + C44*$G$45 + D44*$G$46 + E44*$G$47) -> 1.2 | I44: =IFERROR(H44/G44,"") -> 4
A45: A2 | B45: =IF(C44="","",1/C44) -> 0.33333333 | C45: 1 | D45: =Числовые_ответы!AG3 -> 0.33333333 | E45: =Числовые_ответы!AH3 -> 0.33333333 | F45: =IF(COUNT(B45:E45)<4,"",PRODUCT(B45:E45)^(1/4)) -> 0.43869134 | G45: =IF(F48="","",F45/F48) -> 0.1 | H45: =IF(G45="","",B45*$G$44 + C45*$G$45 + D45*$G$46 + E45*$G$47) -> 0.4 | I45: =IFERROR(H45/G45,"") -> 4
A46: A3 | B46: =IF(D44="","",1/D44) -> 1 | C46: =IF(D45="","",1/D45) -> 3 | D46: 1 | E46: =Числовые_ответы!AI3 -> 1 | F46: =IF(COUNT(B46:E46)<4,"",PRODUCT(B46:E46)^(1/4)) -> 1.316074 | G46: =IF(F48="","",F46/F48) -> 0.3 | H46: =IF(G46="","",B46*$G$44 + C46*$G$45 + D46*$G$46 + E46*$G$47) -> 1.2 | I46: =IFERROR(H46/G46,"") -> 4
A47: A4 | B47: =IF(E44="","",1/E44) -> 1 | C47: =IF(E45="","",1/E45) -> 3 | D47: =IF(E46="","",1/E46) -> 1 | E47: 1 | F47: =IF(COUNT(B47:E47)<4,"",PRODUCT(B47:E47)^(1/4)) -> 1.316074 | G47: =IF(F48="","",F47/F48) -> 0.3 | H47: =IF(G47="","",B47*$G$44 + C47*$G$45 + D47*$G$46 + E47*$G$47) -> 1.2 | I47: =IFERROR(H47/G47,"") -> 4
...

Sheet Бредихин
A1: Индивидуальный МАИ — Бредихин
A2: Все матрицы строятся из ответов формы. Нижний треугольник рассчитывается как обратные значения; веса — нормированное геометрическое среднее строк.
A4: Матрица важности критериев
B5: C1 | C5: C2 | D5: C3 | E5: C4 | F5: C5 | G5: C6 | H5: Геом. ср. | I5: Вес | J5: A·w | K5: λ_i
A6: C1 | B6: 1 | C6: =Числовые_ответы!C4 -> 7 | D6: =Числовые_ответы!D4 -> 5 | E6: =Числовые_ответы!E4 -> 1 | F6: =Числовые_ответы!F4 -> 7 | G6: =Числовые_ответы!G4 -> 7 | H6: =IF(COUNT(B6:G6)<6,"",PRODUCT(B6:G6)^(1/6)) -> 3.4597444 | I6: =IF(H12="","",H6/H12) -> 0.36434014 | J6: =IF(I6="","",B6*$I$6 + C6*$I$7 + D6*$I$8 + E6*$I$9 + F6*$I$10 + G6*$I$11) -> 2.4210818 | K6: =IFERROR(J6/I6,"") -> 6.6451141
A7: C2 | B7: =IF(C6="","",1/C6) -> 0.14285714 | C7: 1 | D7: =Числовые_ответы!H4 -> 3 | E7: =Числовые_ответы!I4 -> 0.14285714 | F7: =Числовые_ответы!J4 -> 7 | G7: =Числовые_ответы!K4 -> 5 | H7: =IF(COUNT(B7:G7)<6,"",PRODUCT(B7:G7)^(1/6)) -> 1.1354435 | I7: =IF(H12="","",H7/H12) -> 0.11957174 | J7: =IF(I7="","",B7*$I$6 + C7*$I$7 + D7*$I$8 + E7*$I$9 + F7*$I$10 + G7*$I$11) -> 0.87919572 | K7: =IFERROR(J7/I7,"") -> 7.3528723
A8: C3 | B8: =IF(D6="","",1/D6) -> 0.2 | C8: =IF(D7="","",1/D7) -> 0.33333333 | D8: 1 | E8: =Числовые_ответы!L4 -> 0.14285714 | F8: =Числовые_ответы!M4 -> 1 | G8: =Числовые_ответы!N4 -> 0.33333333 | H8: =IF(COUNT(B8:G8)<6,"",PRODUCT(B8:G8)^(1/6)) -> 0.38336716 | I8: =IF(H12="","",H8/H12) -> 0.040371781 | J8: =IF(I8="","",B8*$I$6 + C8*$I$7 + D8*$I$8 + E8*$I$9 + F8*$I$10 + G8*$I$11) -> 0.26480332 | K8: =IFERROR(J8/I8,"") -> 6.559119
A9: C4 | B9: =IF(E6="","",1/E6) -> 1 | C9: =IF(E7="","",1/E7) -> 7 | D9: =IF(E8="","",1/E8) -> 7 | E9: 1 | F9: =Числовые_ответы!O4 -> 7 | G9: =Числовые_ответы!P4 -> 7 | H9: =IF(COUNT(B9:G9)<6,"",PRODUCT(B9:G9)^(1/6)) -> 3.6593057 | I9: =IF(H12="","",H9/H12) -> 0.38535562 | J9: =IF(I9="","",B9*$I$6 + C9*$I$7 + D9*$I$8 + E9*$I$9 + F9*$I$10 + G9*$I$11) -> 2.5018254 | K9: =IFERROR(J9/I9,"") -> 6.492251
A10: C5 | B10: =IF(F6="","",1/F6) -> 0.14285714 | C10: =IF(F7="","",1/F7) -> 0.14285714 | D10: =IF(F8="","",1/F8) -> 1 | E10: =IF(F9="","",1/F9) -> 0.14285714 | F10: 1 | G10: =Числовые_ответы!Q4 -> 1 | H10: =IF(COUNT(B10:G10)<6,"",PRODUCT(B10:G10)^(1/6)) -> 0.37796447 | I10: =IF(H12="","",H10/H12) -> 0.039802833 | J10: =IF(I10="","",B10*$I$6 + C10*$I$7 + D10*$I$8 + E10*$I$9 + F10*$I$10 + G10*$I$11) -> 0.25491357 | K10: =IFERROR(J10/I10,"") -> 6.4044076
A11: C6 | B11: =IF(G6="","",1/G6) -> 0.14285714 | C11: =IF(G7="","",1/G7) -> 0.2 | D11: =IF(G8="","",1/G8) -> 3 | E11: =IF(G9="","",1/G9) -> 0.14285714 | F11: =IF(G10="","",1/G10) -> 1 | G11: 1 | H11: =IF(COUNT(B11:G11)<6,"",PRODUCT(B11:G11)^(1/6)) -> 0.48009354 | I11: =IF(H12="","",H11/H12) -> 0.050557881 | J11: =IF(I11="","",B11*$I$6 + C11*$I$7 + D11*$I$8 + E11*$I$9 + F11*$I$10 + G11*$I$11) -> 0.3424898 | K11: =IFERROR(J11/I11,"") -> 6.7742119
H12: =IF(COUNT(H6:H11)<6,"",SUM(H6:H11)) -> 9.4959188 | I12: =IF(COUNT(I6:I11)<6,"",SUM(I6:I11)) -> 1 | J12: λmax | K12: =IF(COUNT(K6:K11)<6,"",AVERAGE(K6:K11)) -> 6.7046626
J13: CI | K13: =IF(K12="","",(K12-6)/(6-1)) -> 0.14093253
J14: RI | K14: =VLOOKUP(6,Шкала_Саати!$D$4:$E$13,2,FALSE) -> 1.24
J15: CR | K15: =IF(COUNT(K13:K14)<2,"",K13/K14) -> 0.11365527
A18: C1: Актуальность и острота проблемы
B19: A1 | C19: A2 | D19: A3 | E19: A4 | F19: Геом. ср. | G19: Вес | H19: A·w | I19: λ_i
A20: A1 | B20: 1 | C20: =Числовые_ответы!R4 -> 0.2 | D20: =Числовые_ответы!S4 -> 0.33333333 | E20: =Числовые_ответы!T4 -> 3 | F20: =IF(COUNT(B20:E20)<4,"",PRODUCT(B20:E20)^(1/4)) -> 0.6687403 | G20: =IF(F24="","",F20/F24) -> 0.12761525 | H20: =IF(G20="","",B20*$G$20 + C20*$G$21 + D20*$G$22 + E20*$G$23) -> 0.53313528 | I20: =IFERROR(H20/G20,"") -> 4.1776767
A21: A2 | B21: =IF(C20="","",1/C20) -> 5 | C21: 1 | D21: =Числовые_ответы!U4 -> 3 | E21: =Числовые_ответы!V4 -> 3 | F21: =IF(COUNT(B21:E21)<4,"",PRODUCT(B21:E21)^(1/4)) -> 2.5900201 | G21: =IF(F24="","",F21/F24) -> 0.49425175 | H21: =IF(G21="","",B21*$G$20 + C21*$G$21 + D21*$G$22 + E21*$G$23) -> 2.266727 | I21: =IFERROR(H21/G21,"") -> 4.586179
A22: A3 | B22: =IF(D20="","",1/D20) -> 3 | C22: =IF(D21="","",1/D21) -> 0.33333333 | D22: 1 | E22: =Числовые_ответы!W4 -> 7 | F22: =IF(COUNT(B22:E22)<4,"",PRODUCT(B22:E22)^(1/4)) -> 1.6265766 | G22: =IF(F24="","",F22/F24) -> 0.31039849 | H22: =IF(G22="","",B22*$G$20 + C22*$G$21 + D22*$G$22 + E22*$G$23) -> 1.3321364 | I22: =IFERROR(H22/G22,"") -> 4.2916973
A23: A4 | B23: =IF(E20="","",1/E20) -> 0.33333333 | C23: =IF(E21="","",1/E21) -> 0.33333333 | D23: =IF(E22="","",1/E22) -> 0.14285714 | E23: 1 | F23: =IF(COUNT(B23:E23)<4,"",PRODUCT(B23:E23)^(1/4)) -> 0.35494811 | G23: =IF(F24="","",F23/F24) -> 0.067734504 | H23: =IF(G23="","",B23*$G$20 + C23*$G$21 + D23*$G$22 + E23*$G$23) -> 0.31936615 | I23: =IFERROR(H23/G23,"") -> 4.7149699
F24: =IF(COUNT(F20:F23)<4,"",SUM(F20:F23)) -> 5.240285 | G24: =IF(COUNT(G20:G23)<4,"",SUM(G20:G23)) -> 1 | H24: λmax | I24: =IF(COUNT(I20:I23)<4,"",AVERAGE(I20:I23)) -> 4.4426307
H25: CI | I25: =IF(I24="","",(I24-4)/(4-1)) -> 0.14754358
H26: RI | I26: =VLOOKUP(4,Шкала_Саати!$D$4:$E$13,2,FALSE) -> 0.9
H27: CR | I27: =IF(COUNT(I25:I26)<2,"",I25/I26) -> 0.16393731
A30: C2: Влияние на продуктивность труда
B31: A1 | C31: A2 | D31: A3 | E31: A4 | F31: Геом. ср. | G31: Вес | H31: A·w | I31: λ_i
A32: A1 | B32: 1 | C32: =Числовые_ответы!X4 -> 1 | D32: =Числовые_ответы!Y4 -> 5 | E32: =Числовые_ответы!Z4 -> 3 | F32: =IF(COUNT(B32:E32)<4,"",PRODUCT(B32:E32)^(1/4)) -> 1.9679897 | G32: =IF(F36="","",F32/F36) -> 0.39651335 | H32: =IF(G32="","",B32*$G$32 + C32*$G$33 + D32*$G$34 + E32*$G$35) -> 1.6511169 | I32: =IFERROR(H32/G32,"") -> 4.1640891
A33: A2 | B33: =IF(C32="","",1/C32) -> 1 | C33: 1 | D33: =Числовые_ответы!AA4 -> 5 | E33: =Числовые_ответы!AB4 -> 3 | F33: =IF(COUNT(B33:E33)<4,"",PRODUCT(B33:E33)^(1/4)) -> 1.9679897 | G33: =IF(F36="","",F33/F36) -> 0.39651335 | H33: =IF(G33="","",B33*$G$32 + C33*$G$33 + D33*$G$34 + E33*$G$35) -> 1.6511169 | I33: =IFERROR(H33/G33,"") -> 4.1640891
A34: A3 | B34: =IF(D32="","",1/D32) -> 0.2 | C34: =IF(D33="","",1/D33) -> 0.2 | D34: 1 | E34: =Числовые_ответы!AC4 -> 3 | F34: =IF(COUNT(B34:E34)<4,"",PRODUCT(B34:E34)^(1/4)) -> 0.58856619 | G34: =IF(F36="","",F34/F36) -> 0.11858515 | H34: =IF(G34="","",B34*$G$32 + C34*$G$33 + D34*$G$34 + E34*$G$35) -> 0.54235495 | I34: =IFERROR(H34/G34,"") -> 4.5735486
A35: A4 | B35: =IF(E32="","",1/E32) -> 0.33333333 | C35: =IF(E33="","",1/E33) -> 0.33333333 | D35: =IF(E34="","",1/E34) -> 0.33333333 | E35: 1 | F35: =IF(COUNT(B35:E35)<4,"",PRODUCT(B35:E35)^(1/4)) -> 0.43869134 | G35: =IF(F36="","",F35/F36) -> 0.088388153 | H35: =IF(G35="","",B35*$G$32 + C35*$G$33 + D35*$G$34 + E35*$G$35) -> 0.39225877 | I35: =IFERROR(H35/G35,"") -> 4.4379112
F36: =IF(COUNT(F32:F35)<4,"",SUM(F32:F35)) -> 4.9632369 | G36: =IF(COUNT(G32:G35)<4,"",SUM(G32:G35)) -> 1 | H36: λmax | I36: =IF(COUNT(I32:I35)<4,"",AVERAGE(I32:I35)) -> 4.3349095
H37: CI | I37: =IF(I36="","",(I36-4)/(4-1)) -> 0.11163649
H38: RI | I38: =VLOOKUP(4,Шкала_Саати!$D$4:$E$13,2,FALSE) -> 0.9
H39: CR | I39: =IF(COUNT(I37:I38)<2,"",I37/I38) -> 0.12404055
A42: C3: Влияние на качество условий труда
B43: A1 | C43: A2 | D43: A3 | E43: A4 | F43: Геом. ср. | G43: Вес | H43: A·w | I43: λ_i
A44: A1 | B44: 1 | C44: =Числовые_ответы!AD4 -> 5 | D44: =Числовые_ответы!AE4 -> 0.11111111 | E44: =Числовые_ответы!AF4 -> 5 | F44: =IF(COUNT(B44:E44)<4,"",PRODUCT(B44:E44)^(1/4)) -> 1.2909944 | G44: =IF(F48="","",F44/F48) -> 0.21396878 | H44: =IF(G44="","",B44*$G$44 + C44*$G$45 + D44*$G$46 + E44*$G$47) -> 1.139767 | I44: =IFERROR(H44/G44,"") -> 5.3267913
A45: A2 | B45: =IF(C44="","",1/C44) -> 0.2 | C45: 1 | D45: =Числовые_ответы!AG4 -> 0.14285714 | E45: =Числовые_ответы!AH4 -> 0.2 | F45: =IF(COUNT(B45:E45)<4,"",PRODUCT(B45:E45)^(1/4)) -> 0.27494162 | G45: =IF(F48="","",F45/F48) -> 0.045568688 | H45: =IF(G45="","",B45*$G$44 + C45*$G$45 + D45*$G$46 + E45*$G$47) -> 0.20133908 | I45: =IFERROR(H45/G45,"") -> 4.4183646
A46: A3 | B46: =IF(D44="","",1/D44) -> 9 | C46: =IF(D45="","",1/D45) -> 7 | D46: 1 | E46: =Числовые_ответы!AI4 -> 3 | F46: =IF(COUNT(B46:E46)<4,"",PRODUCT(B46:E46)^(1/4)) -> 3.7077928 | G46: =IF(F48="","",F46/F48) -> 0.61452774 | H46: =IF(G46="","",B46*$G$44 + C46*$G$45 + D46*$G$46 + E46*$G$47) -> 3.237032 | I46: =IFERROR(H46/G46,"") -> 5.2675116
A47: A4 | B47: =IF(E44="","",1/E44) -> 0.2 | C47: =IF(E45="","",1/E45) -> 5 | D47: =IF(E46="","",1/E46) -> 0.33333333 | E47: 1 | F47: =IF(COUNT(B47:E47)<4,"",PRODUCT(B47:E47)^(1/4)) -> 0.75983569 | G47: =IF(F48="","",F47/F48) -> 0.12593479 | H47: =IF(G47="","",B47*$G$44 + C47*$G$45 + D47*$G$46 + E47*$G$47) -> 0.60141457 | I47: =IFERROR(H47/G47,"") -> 4.775603
...

Sheet Коллективный_МАИ
A1: Коллективный МАИ — агрегирование трёх экспертов
A2: Каждое одинаковое парное суждение трёх экспертов агрегируется геометрическим средним. Затем из коллективных матриц рассчитываются веса и CR.
A4: Коллективная матрица важности критериев
B5: C1 | C5: C2 | D5: C3 | E5: C4 | F5: C5 | G5: C6 | H5: Геом. ср. | I5: Вес | J5: A·w | K5: λ_i
A6: C1 | B6: 1 | C6: =IF(COUNT(Недикова!C6,Символокова!C6,Бредихин!C6)<3,"",POWER(PRODUCT(Недикова!C6,Символокова!C6,Бредихин!C6),1/3)) -> 2.7589242 | D6: =IF(COUNT(Недикова!D6,Символокова!D6,Бредихин!D6)<3,"",POWER(PRODUCT(Недикова!D6,Символокова!D6,Бредихин!D6),1/3)) -> 6.082202 | E6: =IF(COUNT(Недикова!E6,Символокова!E6,Бредихин!E6)<3,"",POWER(PRODUCT(Недикова!E6,Символокова!E6,Бредихин!E6),1/3)) -> 0.69336127 | F6: =IF(COUNT(Недикова!F6,Символокова!F6,Бредихин!F6)<3,"",POWER(PRODUCT(Недикова!F6,Символокова!F6,Бредихин!F6),1/3)) -> 2.7589242 | G6: =IF(COUNT(Недикова!G6,Символокова!G6,Бредихин!G6)<3,"",POWER(PRODUCT(Недикова!G6,Символокова!G6,Бредихин!G6),1/3)) -> 3.2710663 | H6: =IF(COUNT(B6:G6)<6,"",PRODUCT(B6:G6)^(1/6)) -> 2.1720253 | I6: =IF(H12="","",H6/H12) -> 0.28780302 | J6: =IF(I6="","",B6*$I$6 + C6*$I$7 + D6*$I$8 + E6*$I$9 + F6*$I$10 + G6*$I$11) -> 1.764782 | K6: =IFERROR(J6/I6,"") -> 6.1319092
A7: C2 | B7: =IF(C6="","",1/C6) -> 0.36246012 | C7: 1 | D7: =IF(COUNT(Недикова!D7,Символокова!D7,Бредихин!D7)<3,"",POWER(PRODUCT(Недикова!D7,Символокова!D7,Бредихин!D7),1/3)) -> 4.2171633 | E7: =IF(COUNT(Недикова!E7,Символокова!E7,Бредихин!E7)<3,"",POWER(PRODUCT(Недикова!E7,Символокова!E7,Бредихин!E7),1/3)) -> 0.30571071 | F7: =IF(COUNT(Недикова!F7,Символокова!F7,Бредихин!F7)<3,"",POWER(PRODUCT(Недикова!F7,Символокова!F7,Бредихин!F7),1/3)) -> 2.7589242 | G7: =IF(COUNT(Недикова!G7,Символокова!G7,Бредихин!G7)<3,"",POWER(PRODUCT(Недикова!G7,Символокова!G7,Бредихин!G7),1/3)) -> 1.7099759 | H7: =IF(COUNT(B7:G7)<6,"",PRODUCT(B7:G7)^(1/6)) -> 1.140828 | I7: =IF(H12="","",H7/H12) -> 0.15116479 | J7: =IF(I7="","",B7*$I$6 + C7*$I$7 + D7*$I$8 + E7*$I$9 + F7*$I$10 + G7*$I$11) -> 0.95048649 | K7: =IFERROR(J7/I7,"") -> 6.2877507
A8: C3 | B8: =IF(D6="","",1/D6) -> 0.16441414 | C8: =IF(D7="","",1/D7) -> 0.23712622 | D8: 1 | E8: =IF(COUNT(Недикова!E8,Символокова!E8,Бредихин!E8)<3,"",POWER(PRODUCT(Недикова!E8,Символокова!E8,Бредихин!E8),1/3)) -> 0.17878071 | F8: =IF(COUNT(Недикова!F8,Символокова!F8,Бредихин!F8)<3,"",POWER(PRODUCT(Недикова!F8,Символокова!F8,Бредихин!F8),1/3)) -> 0.48074986 | G8: =IF(COUNT(Недикова!G8,Символокова!G8,Бредихин!G8)<3,"",POWER(PRODUCT(Недикова!G8,Символокова!G8,Бредихин!G8),1/3)) -> 0.33333333 | H8: =IF(COUNT(B8:G8)<6,"",PRODUCT(B8:G8)^(1/6)) -> 0.32211149 | I8: =IF(H12="","",H8/H12) -> 0.042681205 | J8: =IF(I8="","",B8*$I$6 + C8*$I$7 + D8*$I$8 + E8*$I$9 + F8*$I$10 + G8*$I$11) -> 0.26055843 | K8: =IFERROR(J8/I8,"") -> 6.104758
A9: C4 | B9: =IF(E6="","",1/E6) -> 1.4422496 | C9: =IF(E7="","",1/E7) -> 3.2710663 | D9: =IF(E8="","",1/E8) -> 5.5934447 | E9: 1 | F9: =IF(COUNT(Недикова!F9,Символокова!F9,Бредихин!F9)<3,"",POWER(PRODUCT(Недикова!F9,Символокова!F9,Бредихин!F9),1/3)) -> 3.2710663 | G9: =IF(COUNT(Недикова!G9,Символокова!G9,Бредихин!G9)<3,"",POWER(PRODUCT(Недикова!G9,Символокова!G9,Бредихин!G9),1/3)) -> 2.7589242 | H9: =IF(COUNT(B9:G9)<6,"",PRODUCT(B9:G9)^(1/6)) -> 2.4896581 | I9: =IF(H12="","",H9/H12) -> 0.32989077 | J9: =IF(I9="","",B9*$I$6 + C9*$I$7 + D9*$I$8 + E9*$I$9 + F9*$I$10 + G9*$I$11) -> 2.0429953 | K9: =IFERROR(J9/I9,"") -> 6.1929448
A10: C5 | B10: =IF(F6="","",1/F6) -> 0.36246012 | C10: =IF(F7="","",1/F7) -> 0.36246012 | D10: =IF(F8="","",1/F8) -> 2.0800838 | E10: =IF(F9="","",1/F9) -> 0.30571071 | F10: 1 | G10: =IF(COUNT(Недикова!G10,Символокова!G10,Бредихин!G10)<3,"",POWER(PRODUCT(Недикова!G10,Символокова!G10,Бредихин!G10),1/3)) -> 1 | H10: =IF(COUNT(B10:G10)<6,"",PRODUCT(B10:G10)^(1/6)) -> 0.6611784 | I10: =IF(H12="","",H10/H12) -> 0.08760908 | J10: =IF(I10="","",B10*$I$6 + C10*$I$7 + D10*$I$8 + E10*$I$9 + F10*$I$10 + G10*$I$11) -> 0.53720017 | K10: =IFERROR(J10/I10,"") -> 6.1317865
A11: C6 | B11: =IF(G6="","",1/G6) -> 0.30571071 | C11: =IF(G7="","",1/G7) -> 0.58480355 | D11: =IF(G8="","",1/G8) -> 3 | E11: =IF(G9="","",1/G9) -> 0.36246012 | F11: =IF(G10="","",1/G10) -> 1 | G11: 1 | H11: =IF(COUNT(B11:G11)<6,"",PRODUCT(B11:G11)^(1/6)) -> 0.76111513 | I11: =IF(H12="","",H11/H12) -> 0.10085114 | J11: =IF(I11="","",B11*$I$6 + C11*$I$7 + D11*$I$8 + E11*$I$9 + F11*$I$10 + G11*$I$11) -> 0.61246225 | K11: =IFERROR(J11/I11,"") -> 6.0729333
H12: =IF(COUNT(H6:H11)<6,"",SUM(H6:H11)) -> 7.5469164 | I12: =IF(COUNT(I6:I11)<6,"",SUM(I6:I11)) -> 1 | J12: λmax | K12: =IF(COUNT(K6:K11)<6,"",AVERAGE(K6:K11)) -> 6.1536804
J13: CI | K13: =IF(K12="","",(K12-6)/(6-1)) -> 0.030736082
J14: RI | K14: =VLOOKUP(6,Шкала_Саати!$D$4:$E$13,2,FALSE) -> 1.24
J15: CR | K15: =IF(COUNT(K13:K14)<2,"",K13/K14) -> 0.024787163
A18: Коллективная матрица альтернатив по C1: Актуальность и острота проблемы
B19: A1 | C19: A2 | D19: A3 | E19: A4 | F19: Геом. ср. | G19: Вес | H19: A·w | I19: λ_i
A20: A1 | B20: 1 | C20: =IF(COUNT(Недикова!C20,Символокова!C20,Бредихин!C20)<3,"",POWER(PRODUCT(Недикова!C20,Символокова!C20,Бредихин!C20),1/3)) -> 0.2 | D20: =IF(COUNT(Недикова!D20,Символокова!D20,Бредихин!D20)<3,"",POWER(PRODUCT(Недикова!D20,Символокова!D20,Бредихин!D20),1/3)) -> 0.28114422 | E20: =IF(COUNT(Недикова!E20,Символокова!E20,Бредихин!E20)<3,"",POWER(PRODUCT(Недикова!E20,Символокова!E20,Бредихин!E20),1/3)) -> 1.4422496 | F20: =IF(COUNT(B20:E20)<4,"",PRODUCT(B20:E20)^(1/4)) -> 0.53364187 | G20: =IF(F24="","",F20/F24) -> 0.101073 | H20: =IF(G20="","",B20*$G$20 + C20*$G$21 + D20*$G$22 + E20*$G$23) -> 0.40530862 | I20: =IFERROR(H20/G20,"") -> 4.0100584
A21: A2 | B21: =IF(C20="","",1/C20) -> 5 | C21: 1 | D21: =IF(COUNT(Недикова!D21,Символокова!D21,Бредихин!D21)<3,"",POWER(PRODUCT(Недикова!D21,Символокова!D21,Бредихин!D21),1/3)) -> 2.0800838 | E21: =IF(COUNT(Недикова!E21,Символокова!E21,Бредихин!E21)<3,"",POWER(PRODUCT(Недикова!E21,Символокова!E21,Бредихин!E21),1/3)) -> 4.2171633 | F21: =IF(COUNT(B21:E21)<4,"",PRODUCT(B21:E21)^(1/4)) -> 2.5734623 | G21: =IF(F24="","",F21/F24) -> 0.48741969 | H21: =IF(G21="","",B21*$G$20 + C21*$G$21 + D21*$G$22 + E21*$G$23) -> 2.0163532 | I21: =IFERROR(H21/G21,"") -> 4.1367906
A22: A3 | B22: =IF(D20="","",1/D20) -> 3.5568933 | C22: =IF(D21="","",1/D21) -> 0.48074986 | D22: 1 | E22: =IF(COUNT(Недикова!E22,Символокова!E22,Бредихин!E22)<3,"",POWER(PRODUCT(Недикова!E22,Символокова!E22,Бредихин!E22),1/3)) -> 5.5934447 | F22: =IF(COUNT(B22:E22)<4,"",PRODUCT(B22:E22)^(1/4)) -> 1.7586011 | G22: =IF(F24="","",F22/F24) -> 0.33308309 | H22: =IF(G22="","",B22*$G$20 + C22*$G$21 + D22*$G$22 + E22*$G$23) -> 1.3655774 | I22: =IFERROR(H22/G22,"") -> 4.0998101
A23: A4 | B23: =IF(E20="","",1/E20) -> 0.69336127 | C23: =IF(E21="","",1/E21) -> 0.23712622 | D23: =IF(E22="","",1/E22) -> 0.17878071 | E23: 1 | F23: =IF(COUNT(B23:E23)<4,"",PRODUCT(B23:E23)^(1/4)) -> 0.4140616 | G23: =IF(F24="","",F23/F24) -> 0.07842422 | H23: =IF(G23="","",B23*$G$20 + C23*$G$21 + D23*$G$22 + E23*$G$23) -> 0.32363314 | I23: =IFERROR(H23/G23,"") -> 4.1266989
F24: =IF(COUNT(F20:F23)<4,"",SUM(F20:F23)) -> 5.2797669 | G24: =IF(COUNT(G20:G23)<4,"",SUM(G20:G23)) -> 1 | H24: λmax | I24: =IF(COUNT(I20:I23)<4,"",AVERAGE(I20:I23)) -> 4.0933395
H25: CI | I25: =IF(I24="","",(I24-4)/(4-1)) -> 0.031113166
H26: RI | I26: =VLOOKUP(4,Шкала_Саати!$D$4:$E$13,2,FALSE) -> 0.9
H27: CR | I27: =IF(COUNT(I25:I26)<2,"",I25/I26) -> 0.034570184
A30: Коллективная матрица альтернатив по C2: Влияние на продуктивность труда
B31: A1 | C31: A2 | D31: A3 | E31: A4 | F31: Геом. ср. | G31: Вес | H31: A·w | I31: λ_i
A32: A1 | B32: 1 | C32: =IF(COUNT(Недикова!C32,Символокова!C32,Бредихин!C32)<3,"",POWER(PRODUCT(Недикова!C32,Символокова!C32,Бредихин!C32),1/3)) -> 0.36246012 | D32: =IF(COUNT(Недикова!D32,Символокова!D32,Бредихин!D32)<3,"",POWER(PRODUCT(Недикова!D32,Символокова!D32,Бредихин!D32),1/3)) -> 1 | E32: =IF(COUNT(Недикова!E32,Символокова!E32,Бредихин!E32)<3,"",POWER(PRODUCT(Недикова!E32,Символокова!E32,Бредихин!E32),1/3)) -> 1.4422496 | F32: =IF(COUNT(B32:E32)<4,"",PRODUCT(B32:E32)^(1/4)) -> 0.85030584 | G32: =IF(F36="","",F32/F36) -> 0.18443494 | H32: =IF(G32="","",B32*$G$32 + C32*$G$33 + D32*$G$34 + E32*$G$35) -> 0.73857941 | I32: =IFERROR(H32/G32,"") -> 4.0045524
A33: A2 | B33: =IF(C32="","",1/C32) -> 2.7589242 | C33: 1 | D33: =IF(COUNT(Недикова!D33,Символокова!D33,Бредихин!D33)<3,"",POWER(PRODUCT(Недикова!D33,Символокова!D33,Бредихин!D33),1/3)) -> 3.5568933 | E33: =IF(COUNT(Недикова!E33,Символокова!E33,Бредихин!E33)<3,"",POWER(PRODUCT(Недикова!E33,Символокова!E33,Бредихин!E33),1/3)) -> 3 | F33: =IF(COUNT(B33:E33)<4,"",PRODUCT(B33:E33)^(1/4)) -> 2.3293404 | G33: =IF(F36="","",F33/F36) -> 0.50524382 | H33: =IF(G33="","",B33*$G$32 + C33*$G$33 + D33*$G$34 + E33*$G$35) -> 2.0414397 | I33: =IFERROR(H33/G33,"") -> 4.040504
A34: A3 | B34: =IF(D32="","",1/D32) -> 1 | C34: =IF(D33="","",1/D33) -> 0.28114422 | D34: 1 | E34: =IF(COUNT(Недикова!E34,Символокова!E34,Бредихин!E34)<3,"",POWER(PRODUCT(Недикова!E34,Символокова!E34,Бредихин!E34),1/3)) -> 1.4422496 | F34: =IF(COUNT(B34:E34)<4,"",PRODUCT(B34:E34)^(1/4)) -> 0.79798071 | G34: =IF(F36="","",F34/F36) -> 0.1730854 | H34: =IF(G34="","",B34*$G$32 + C34*$G$33 + D34*$G$34 + E34*$G$35) -> 0.69749505 | I34: =IFERROR(H34/G34,"") -> 4.029774
A35: A4 | B35: =IF(E32="","",1/E32) -> 0.69336127 | C35: =IF(E33="","",1/E33) -> 0.33333333 | D35: =IF(E34="","",1/E34) -> 0.69336127 | E35: 1 | F35: =IF(COUNT(B35:E35)<4,"",PRODUCT(B35:E35)^(1/4)) -> 0.63270239 | G35: =IF(F36="","",F35/F36) -> 0.13723583 | H35: =IF(G35="","",B35*$G$32 + C35*$G$33 + D35*$G$34 + E35*$G$35) -> 0.5535412 | I35: =IFERROR(H35/G35,"") -> 4.0335034
F36: =IF(COUNT(F32:F35)<4,"",SUM(F32:F35)) -> 4.6103294 | G36: =IF(COUNT(G32:G35)<4,"",SUM(G32:G35)) -> 1 | H36: λmax | I36: =IF(COUNT(I32:I35)<4,"",AVERAGE(I32:I35)) -> 4.0270834
H37: CI | I37: =IF(I36="","",(I36-4)/(4-1)) -> 0.0090278158
H38: RI | I38: =VLOOKUP(4,Шкала_Саати!$D$4:$E$13,2,FALSE) -> 0.9
H39: CR | I39: =IF(COUNT(I37:I38)<2,"",I37/I38) -> 0.010030906
A42: Коллективная матрица альтернатив по C3: Влияние на качество условий труда
B43: A1 | C43: A2 | D43: A3 | E43: A4 | F43: Геом. ср. | G43: Вес | H43: A·w | I43: λ_i
A44: A1 | B44: 1 | C44: =IF(COUNT(Недикова!C44,Символокова!C44,Бредихин!C44)<3,"",POWER(PRODUCT(Недикова!C44,Символокова!C44,Бредихин!C44),1/3)) -> 3.5568933 | D44: =IF(COUNT(Недикова!D44,Символокова!D44,Бредихин!D44)<3,"",POWER(PRODUCT(Недикова!D44,Символокова!D44,Бредихин!D44),1/3)) -> 0.48074986 | E44: =IF(COUNT(Недикова!E44,Символокова!E44,Бредихин!E44)<3,"",POWER(PRODUCT(Недикова!E44,Символокова!E44,Бредихин!E44),1/3)) -> 2.4662121 | F44: =IF(COUNT(B44:E44)<4,"",PRODUCT(B44:E44)^(1/4)) -> 1.4330294 | G44: =IF(F48="","",F44/F48) -> 0.29663956 | H44: =IF(G44="","",B44*$G$44 + C44*$G$45 + D44*$G$46 + E44*$G$47) -> 1.2389116 | I44: =IFERROR(H44/G44,"") -> 4.1764882
A45: A2 | B45: =IF(C44="","",1/C44) -> 0.28114422 | C45: 1 | D45: =IF(COUNT(Недикова!D45,Символокова!D45,Бредихин!D45)<3,"",POWER(PRODUCT(Недикова!D45,Символокова!D45,Бредихин!D45),1/3)) -> 0.21196797 | E45: =IF(COUNT(Недикова!E45,Символокова!E45,Бредихин!E45)<3,"",POWER(PRODUCT(Недикова!E45,Символокова!E45,Бредихин!E45),1/3)) -> 0.28114422 | F45: =IF(COUNT(B45:E45)<4,"",PRODUCT(B45:E45)^(1/4)) -> 0.35977596 | G45: =IF(F48="","",F45/F48) -> 0.074474244 | H45: =IF(G45="","",B45*$G$44 + C45*$G$45 + D45*$G$46 + E45*$G$47) -> 0.30424332 | I45: =IFERROR(H45/G45,"") -> 4.0852153
A46: A3 | B46: =IF(D44="","",1/D44) -> 2.0800838 | C46: =IF(D45="","",1/D45) -> 4.717694 | D46: 1 | E46: =IF(COUNT(Недикова!E46,Символокова!E46,Бредихин!E46)<3,"",POWER(PRODUCT(Недикова!E46,Символокова!E46,Бредихин!E46),1/3)) -> 2.0800838 | F46: =IF(COUNT(B46:E46)<4,"",PRODUCT(B46:E46)^(1/4)) -> 2.1255575 | G46: =IF(F48="","",F46/F48) -> 0.43999407 | H46: =IF(G46="","",B46*$G$44 + C46*$G$45 + D46*$G$46 + E46*$G$47) -> 1.8012874 | I46: =IFERROR(H46/G46,"") -> 4.0938901
A47: A4 | B47: =IF(E44="","",1/E44) -> 0.40548013 | C47: =IF(E45="","",1/E45) -> 3.5568933 | D47: =IF(E46="","",1/E46) -> 0.48074986 | E47: 1 | F47: =IF(COUNT(B47:E47)<4,"",PRODUCT(B47:E47)^(1/4)) -> 0.91251475 | G47: =IF(F48="","",F47/F48) -> 0.18889213 | H47: =IF(G47="","",B47*$G$44 + C47*$G$45 + D47*$G$46 + E47*$G$47) -> 0.7855976 | I47: =IFERROR(H47/G47,"") -> 4.1589748
...

Sheet Итоги
A1: Итоги коллективного МАИ
A3: Код | B3: Критерий | C3: Коллективный вес | E3: Концепция | F3: Глобальный приоритет | G3: Место | H3: Статус
A4: C1 | B4: Актуальность и острота проблемы | C4: =IF(Коллективный_МАИ!I6="","",Коллективный_МАИ!I6) -> 0.28780302 | E4: A1 — Корпоративный ассистент продуктивности и благополучия | F4: =IF(Коллективный_МАИ!H92="","",Коллективный_МАИ!H92) -> 0.17550954 | G4: =IF(Коллективный_МАИ!I92="","",Коллективный_МАИ!I92) -> 3 | H4: =IF(G4="","",IF(G4=1,"Лидер",""))
A5: C2 | B5: Влияние на продуктивность труда | C5: =IF(Коллективный_МАИ!I7="","",Коллективный_МАИ!I7) -> 0.15116479 | E5: A2 — Система автоматизации внутренних заявок и сервисных запросов | F5: =IF(Коллективный_МАИ!H93="","",Коллективный_МАИ!H93) -> 0.44093762 | G5: =IF(Коллективный_МАИ!I93="","",Коллективный_МАИ!I93) -> 1 | H5: =IF(G5="","",IF(G5=1,"Лидер","")) -> Лидер
A6: C3 | B6: Влияние на качество условий труда | C6: =IF(Коллективный_МАИ!I8="","",Коллективный_МАИ!I8) -> 0.042681205 | E6: A3 — Корпоративный портал обучения и адаптации сотрудников | F6: =IF(Коллективный_МАИ!H94="","",Коллективный_МАИ!H94) -> 0.22638832 | G6: =IF(Коллективный_МАИ!I94="","",Коллективный_МАИ!I94) -> 2 | H6: =IF(G6="","",IF(G6=1,"Лидер",""))
A7: C4 | B7: Экономическая выгода для предприятия | C7: =IF(Коллективный_МАИ!I9="","",Коллективный_МАИ!I9) -> 0.32989077 | E7: A4 — Система оптимизации графика смен и загрузки персонала | F7: =IF(Коллективный_МАИ!H95="","",Коллективный_МАИ!H95) -> 0.15716452 | G7: =IF(Коллективный_МАИ!I95="","",Коллективный_МАИ!I95) -> 4 | H7: =IF(G7="","",IF(G7=1,"Лидер",""))
A8: C5 | B8: Техническая сложность реализации | C8: =IF(Коллективный_МАИ!I10="","",Коллективный_МАИ!I10) -> 0.08760908
A9: C6 | B9: Ресурсоёмкость разработки (стоимость и сроки) | C9: =IF(Коллективный_МАИ!I11="","",Коллективный_МАИ!I11) -> 0.10085114
A12: Матрица | B12: Недикова | C12: Символокова | D12: Бредихин | E12: Коллективная | F12: Интерпретация
A13: Критерии | B13: =IF(Недикова!K15="","",Недикова!K15) -> 0.074508291 | C13: =IF(Символокова!K15="","",Символокова!K15) -> 0.0070400613 | D13: =IF(Бредихин!K15="","",Бредихин!K15) -> 0.11365527 | E13: =IF(Коллективный_МАИ!K15="","",Коллективный_МАИ!K15) -> 0.024787163 | F13: =IF(COUNT(B13:E13)<4,"",IF(MAX(B13:E13)<=0.1,"CR приемлем","Проверить сравнения")) -> Проверить сравнения
A14: C1 | B14: =IF(Недикова!I27="","",Недикова!I27) -> 0.042474731 | C14: =IF(Символокова!I27="","",Символокова!I27) -> 0 | D14: =IF(Бредихин!I27="","",Бредихин!I27) -> 0.16393731 | E14: =IF(Коллективный_МАИ!I27="","",Коллективный_МАИ!I27) -> 0.034570184 | F14: =IF(COUNT(B14:E14)<4,"",IF(MAX(B14:E14)<=0.1,"CR приемлем","Проверить сравнения")) -> Проверить сравнения
A15: C2 | B15: =IF(Недикова!I39="","",Недикова!I39) -> 0.056762951 | C15: =IF(Символокова!I39="","",Символокова!I39) -> 0.021071899 | D15: =IF(Бредихин!I39="","",Бредихин!I39) -> 0.12404055 | E15: =IF(Коллективный_МАИ!I39="","",Коллективный_МАИ!I39) -> 0.010030906 | F15: =IF(COUNT(B15:E15)<4,"",IF(MAX(B15:E15)<=0.1,"CR приемлем","Проверить сравнения")) -> Проверить сравнения
A16: C3 | B16: =IF(Недикова!I51="","",Недикова!I51) -> 0.042474731 | C16: =IF(Символокова!I51="","",Символокова!I51) -> 0 | D16: =IF(Бредихин!I51="","",Бредихин!I51) -> 0.35076578 | E16: =IF(Коллективный_МАИ!I51="","",Коллективный_МАИ!I51) -> 0.047645227 | F16: =IF(COUNT(B16:E16)<4,"",IF(MAX(B16:E16)<=0.1,"CR приемлем","Проверить сравнения")) -> Проверить сравнения
A17: C4 | B17: =IF(Недикова!I63="","",Недикова!I63) -> 0.056762951 | C17: =IF(Символокова!I63="","",Символокова!I63) -> 0.076621634 | D17: =IF(Бредихин!I63="","",Бредихин!I63) -> 0.079779631 | E17: =IF(Коллективный_МАИ!I63="","",Коллективный_МАИ!I63) -> 0.0083293301 | F17: =IF(COUNT(B17:E17)<4,"",IF(MAX(B17:E17)<=0.1,"CR приемлем","Проверить сравнения")) -> CR приемлем
A18: C5 | B18: =IF(Недикова!I75="","",Недикова!I75) -> 0.017392322 | C18: =IF(Символокова!I75="","",Символокова!I75) -> 0.016067186 | D18: =IF(Бредихин!I75="","",Бредихин!I75) -> 0.062111579 | E18: =IF(Коллективный_МАИ!I75="","",Коллективный_МАИ!I75) -> 0.0025762619 | F18: =IF(COUNT(B18:E18)<4,"",IF(MAX(B18:E18)<=0.1,"CR приемлем","Проверить сравнения")) -> CR приемлем
A19: C6 | B19: =IF(Недикова!I87="","",Недикова!I87) -> 0.15224282 | C19: =IF(Символокова!I87="","",Символокова!I87) -> 0.016067186 | D19: =IF(Бредихин!I87="","",Бредихин!I87) -> 0.10254211 | E19: =IF(Коллективный_МАИ!I87="","",Коллективный_МАИ!I87) -> 0.041404146 | F19: =IF(COUNT(B19:E19)<4,"",IF(MAX(B19:E19)<=0.1,"CR приемлем","Проверить сравнения")) -> Проверить сравнения

Sheet Формулы_и_методика
A1: Формулы и методика расчёта
A3: Этап | B3: Формула / правило
A4: 1. Кодирование ответа | B4: Вербальная оценка → число Саати
A5: 2. Обратная ячейка | B5: a_ji = 1 / a_ij
A6: 3. Геом. среднее строки | B6: g_i = (Π_j a_ij)^(1/n)
A7: 4. Нормирование | B7: w_i = g_i / Σ g_i
A8: 5. Проверка λmax | B8: λ_i = (A·w)_i / w_i; λmax = average(λ_i)
A9: 6. Индекс согласованности | B9: CI = (λmax - n)/(n - 1)
A10: 7. Отношение согласованности | B10: CR = CI / RI
A11: 8. Коллективное суждение | B11: a_ij(group) = (a_ij(1)·a_ij(2)·a_ij(3))^(1/3)
A12: 9. Глобальный приоритет | B12: P(A_i) = Σ_j w_j·p_ij
A14: Методическое решение | B14: Что принято | C14: Почему
A15: Тип МАИ | B15: Чёткий коллективный МАИ | C15: В задании указан чёткий коллективный МАИ; нечёткие треугольные оценки не используются.
A16: Эксперты | B16: 3 равноправных эксперта | C16: Недикова, Символокова, Бредихин.
A17: Агрегирование | B17: Геометрическое среднее суждений | C17: Выбран стандартный для взаимно-обратных парных сравнений способ.
A18: Шкала формы | B18: 9 вербальных категорий финальной формы: «Первый вариант… / Равнозначны / Второй вариант…» | C18: Используются 1, 3, 5, 7, 9 и обратные значения; 2, 4, 6, 8 не предлагаются, чтобы не перегружать опрос.
